Workbook
Name lista: 'Tulajdonos besorolás opciók'!$B$16:$B$21
Name TermSzem: OFFSET(PÁLYÁZÓ!$N$30,0,0,COUNTA(PÁLYÁZÓ!$N$30:$O$30:'PÁLYÁZÓ'!$N7),1)

Sheet Útmutató
A1: DIMOP Plusz-1.2.6/B-26 5/a. sz. melléklet - Nyilatkozat KKV minősítéshez - komplex A sablon NEM minden fülének kitöltése szükséges! A PÁLYÁZÓ fül kitöltése minden esetben kötelező, az azon jelzettek alapján pedig további lapfülek kitöltése szükséges, mely függ a pályázó vállalkozás kapcsolati hálójától (hány kapcsolódó -, illetve partnervállalkozással rendelkezik).
A6: FIGYELEM! Az 5/a. sz. melléklet - Nyilatkozat KKV minősítéshez - komplex sablon kitöltése abban az esetben szükséges, - ha a pályázó vállalkozás tulajdonosa nem természetes személy, vagy - ha a pályázó vállalkozás tulajdonosa természetes személy, de egyéb más vállalkozásban is van befolyása, vagy - ha a pályázó vállalkozás rendelkezik egyéb más vállakozásban befolyással. Pl. Ha egy Bt. nyújt be támogatási kérelmet, melynek a tulajdonosa egy Kft. Ha a pályázó vállalkozás tulajdonosa egy vagy több természetes személy, azonban a természetes személyeknek van egyéb más vállalkozásban is befolyása. Abban az esetben, ha a fentebbiek nem állnak fenn, akkor a pályázó vállakozás KKV minősítéséhez egy egyszerűsített sablon áll rendelkezésre (5/b. sz. melléklet - Nyilatkozat KKV minősítéshez - egyszerűsített), azt szükséges kitölteni és benyújtani, mely szintén elérhető a palyazat.gov.hu weboldalon. Pl. A pályázó vállalkozás egyéni vállalkozó, akinek egyéb vállalkozásban nincs befolyása. A pályázó vállalkozás Bt., melynek tulajdonosai természetes személyek, akiknek nincs más vállalkozásban befolyása, továbbá a pályázó vállalkozásnak (Bt.-nek) sincs egyéb más vállalkozásban. befolyása
A16: Kitöltési Útmutató A KKV minősítés meghatározása a kis-és középvállalkozásokról, fejlődésük támogatásáról szóló 2004. évi XXXIV. törvény (továbbiakban: KKV tv.) alapján, az abban meghatározott fogalmak, szabályok szerint történik. Felhívjuk a figyelmet, hogy a KKV tv. 19. § 5. pontja értelmében vállalkozásnak minősül: „a gazdasági tevékenységet folytató jogalany, különösen az egyéni vállalkozó, az egyéni cég, a gazdasági társaság, az ügyvédi iroda, a szövetkezet, a vízitársulat, a víziközmű társulat, az erdőbirtokossági társulat, továbbá a mezőgazdasági termeléssel, halgazdálkodással, mezőgazdasági feldolgozással és forgalmazással, erdőgazdálkodással és vadgazdálkodással foglalkozó jogalany és természetes személy, a vagyonkezelő alapítvány, a külföldi vállalkozás magyarországi fióktelepe, az egyházi jogi személy;” Fontos megjegyezni, hogy a KKV tv. nem taxatív módon sorolja fel a vállalkozásokat, hanem példálózó jelleggel kiemeli a gyakori vállalkozásokat, de nem csak kizárólag ezen formák minősülhetnek vállalkozásoknak. A DIMOP Plusz-1.2.6/B-26 kódszámú felhívásra mikro-, és kisvállalkozások nyújthatnak be támogatási kérelmet. Jelen dokumentum célja, hogy ez alapján megállapításra kerüljön a támogatást igénylő vállalkozásról a KKV minősítése. A KKV minősítés elvégzéséhez és a dokumentum megfelelő kitöltéséhez a támogatást igénylő vállalkozásnak szükséges megadnia tulajdonosi adatait, valamint az elmúlt három üzleti évre vonatkozóan (amennyiben releváns) a pénzügyi, létszám adatait, továbbá amennyiben rendelkezik partner-, vagy kapcsolódó vállalkozással, akkor ezen vállalkozások adatait. Ahhoz, hogy egy vállalkozás mikro-, vagy kisvállalkozásnak minősüljön, meg kell felelnie a foglalkoztatotti létszámra vonatkozó kritériumnak. Az éves nettó árbevételre vagy a mérlegfőösszegre vonatkozó küszöbérték közül azonban választhat (amennyiben két pénzügyi adattal rendelkezik), mindkét követelménynek nem kell megfelelnie, vagyis az egyiket túllépheti anélkül, hogy az a KKV státuszát befolyásolná. A KKV kategórián belül mikrovállalkozásnak minősül az a vállalkozás, amelynek - összes foglalkoztatotti létszáma 10 főnél kevesebb, és - éves nettó árbevétele vagy mérlegfőösszege legfeljebb 2 millió eurónak megfelelő forintösszeg. A KKV kategórián belül kisvállalkozásnak minősül az a vállalkozás, amelynek - összes foglalkoztatotti létszáma 50 főnél kevesebb, és - éves nettó árbevétele vagy mérlegfőösszege legfeljebb 10 millió eurónak megfelelő forintösszeg. Tehát mikrovállalkozásnak fog minősülni az a vállalkozás, melynek foglalkoztatotti létszáma 9 fő, éves nettó árbevétele 1,5 millió eurónak megfelelő forintösszeg, de mérlegfőösszege 2,5 millió eurónak megfelelő forintösszeg. A táblázatokban a mérlegfőösszeg, valamint éves nettó árbevétel kapcsán az adatokat forintban kell megadnia, a táblázat automatikusan átszámítja azt euróra, melynek során a Magyar Nemzeti Bank által megállapított, a vállalkozás üzleti évének lezárásakor érvényes deviza középárfolyamot alkalmazzuk. A KKV törvény rögzít egy kétéves szabályt, amely alapján amennyiben egy vállalkozás éves szinten túllépi a meghatározott foglalkoztatotti létszám vagy pénzügyi határértékeket (nettó árbevétel, mérlegfőösszeg), vagy elmarad azoktól, akkor ennek eredményeként csak abban az esetben veszíti el, illetve nyeri el a KKV minősítést, ha két egymást követő beszámolási időszakban túllépi az adott határértékeket vagy elmarad azoktól, ezért szükséges megadni három évre vonatkozóan az adatokat. A KKV besoroláshoz azt is szükséges vizsgálni, hogy a vállalkozásnak van-e olyan kapcsolata, mely miatt a fentebb részletezett kritériumok vizsgálatakor egyéb más vállalkozás adatait is figyelembe szükséges venni (egybe kell számítani). Ahhoz, hogy a vállalkozás esetén a számításba veendő és a küszöbértékekkel összevetendő adatokat megadja, először is meg kell állapítani, hogy a vállalkozás: • önálló vállalkozásnak minősül-e, vagy • rendelkezik-e partnervállalkozással, és/vagy • rendelkezik-e kapcsolódó vállalkozással. A KKV tv. 4. § -a részletezi az önálló vállalkozás, a partnervállalkozás, valamint a kapcsolódó vállalkozás fogalmát. "(3) Kapcsolódó vállalkozások azok, amelyek egymással az alábbiakban felsorolt valamely kapcsolatban állnak: a) egy vállalkozás egy másik vállalkozásban a szavazatok többségével rendelkezik, vagy b) egy vállalkozás egy másik vállalkozásban jogosult arra, hogy a vezető tisztségviselők vagy a felügyelő bizottság tagjai többségét megválassza vagy visszahívja, vagy c) egy vállalkozás egy másik vállalkozás felett a tulajdonosokkal (részvényesekkel) kötött szerződés vagy a létesítő okirat rendelkezése alapján – függetlenül a tulajdoni hányadtól, a szavazati aránytól, a megválasztási és visszahívási jogtól – döntő irányítást, ellenőrzést gyakorol, vagy d) egy vállalkozás egy másik vállalkozásban – más tulajdonosokkal (részvényesekkel) kötött megállapodás alapján – a szavazatok többségét egyedül birtokolja. (4) Kapcsolódó vállalkozásnak minősülnek azok a vállalkozások és a 19. § 1. pontjában meghatározott befektetők is, amelyek egy vagy több másik vállalkozáson keresztül állnak egymással a (3) bekezdésben meghatározott kapcsolatban. (5) Kapcsolódó vállalkozásnak minősülnek továbbá azok a vállalkozások, amelyek egy természetes személy vagy közösen fellépő természetes személyek egy csoportja révén a (3) és (4) bekezdésben meghatározott jellegű kapcsolatban állnak egymással, amennyiben tevékenységüket vagy tevékenységük egy részét az érintett piacon vagy egymással szomszédos piacokon folytatják." "(2) Partnervállalkozások azok a vállalkozások, a) amelyek nem minősülnek kapcsolódó vállalkozásoknak, és b) amelyek között olyan kapcsolat áll fenn, hogy egy vállalkozás kizárólagosan vagy egy vagy több kapcsolódó vállalkozással közösen valamely másik vállalkozás jegyzett tőkéjének vagy a szavazati jogának legalább 25%-ával rendelkezik." A három vállalkozástípus mindegyikére más és más számítást kell alkalmazni, ezek pedig végső soron meghatározzák, hogy a vállalkozás megfelel-e a KKV fogalom meghatározásában megállapított különféle felső határértékeknek. Amennyiben a táblázatban feltüntetésre kerül partner-, kapcsolódó vállalkozás, azzal automatikusan számol a KKV minősítés meghatározásakor, partnervállalkozás esetében az adatok arányos részét, kapcsolódó vállalkozás esetében pedig annak valamennyi adatát figyelembe veszi. A „Nyilatkozat KKV minősítéshez – komplex” dokumentum ’PÁLYÁZÓ’ munkalapjának kitöltése minden esetben kötelező azzal a kitétellel, hogy kizárólag a támogatást igénylő vállalkozás esetében releváns adatok feltüntetése szükséges. Ehhez kérjük, kövesse a munkalapon található segédleteket és információkat, melyek blokkokra és alblokkokra bontva vezetik végig a nyilatkozat kitöltését és segítséget nyújtanak a további munkalapok esetleges kitöltése vonatkozásában is. A ’PÁLYÁZÓ’ munkalap I. blokkjában a támogatást igénylő vállalkozás alap-, és gazdálkodási adatainak feltüntetése szükséges, a blokkhoz tartozó segédletben meghatározottak alapján. Kérjük, kizárólag a vállalkozás saját adatait szerepeltesse, még akkor is, ha összevont, (konszolidált) beszámolójában szerepel más vállalkozás adata; vagy a támogatást igénylő vállalkozás szerepel más vállalkozás összevont (konszolidált) beszámolójában. Amennyiben pedig rendelkezik partner-, és/vagy kapcsolódó vállalkozással, akkor azok adatait a további blokkokban/munkalapokon szükséges feltüntetni vállalkozásonként. A KKV besorolás, valamint az esetleges partner és kapcsolódó vállalkozások meghatározásához a támogatást igénylő vállalkozás tulajdonosi összetételének vizsgálatára is szükség van. A tulajdonosi adatok feltüntetése jelen nyilatkozat ’PÁLYÁZÓ’ munkalap II. blokkjában történik. A II.1. alblokk kitöltése minden esetben kötelező, míg a II.2.-II.6. alblokkok kitöltése csak releváns esetekben szükséges, ezért kérjük, vegye figyelembe, hogy az egyes alblokkok esetében a táblázat kéri-e az adott alblokk kitöltését. Amennyiben igen, úgy az alblokk kitöltése kötelező, az alblokkhoz tartozó segédletekben meghatározottak alapján. Felhívjuk a figyelmet, hogy amennyiben adószámmal rendelkező magánszemély, egyéni vállalkozó köthető a támogatást igénylő vállalkozáshoz, akkor a vizsgálathoz szükséges figyelembe venni a KKV törvény 19. § 5. pontja szerinti, vállalkozásról szóló meghatározást (lásd fentebb), mivel ebben az esetben partner -, vagy kapcsolódó vállalkozásként szükséges feltüntetni. A KKV minősítés során továbbá szükséges a támogatást igénylő vállalkozás más vállalkozás(ok)ban lévő befolyásait vizsgálni, ezért a ’PÁLYÁZÓ’ munkalap III. blokkjának kitöltése minden esetben kötelező. Kérjük, a kitöltéshez vegye figyelembe a blokkhoz tartozó segédletben leírtakat. Fentieken túl, egyes esetekben szükség lehet további munkalapok (’KAPCSOLÓDÓ PIAC’, ’KAPCSOLÓDÓ’, ’PARTNER’, ’KAPCSOLÓDÓ KÉK’, ’PARTNER KÉK’) kitöltésére is. Ezen kitöltési kötelezettségekre minden esetben iránymutatást adnak a táblázat ’PÁLYÁZÓ’ munkalapján látható blokkok/alblokkok megnevezése melletti figyelemfelhívó szövegek, ezért kérjük azok figyelembevételét az adatok kitöltése során. Amennyiben a pályázó vállalkozás tulajdonosi szerkezete alapján rendelkezik kapcsolódó -, vagy partnervállalkozással, akkor a ’PÁLYÁZÓ’ munkalapon az adott táblázat utolsó oszlopában („Vállalkozás adatlapja”) talál soronként egy hivatkozást, melyre kattintva az elnavigálja a megfelelő zöld munkalapra, ahol a szükséges adatokat megadhatja. Amennyiben a pályázó vállalkozás rendelkezik más egyéb vállalkozás(ok)ban befolyással, akkor a KAPCSOLÓDÓ KÉK vagy PARTNER KÉK munkalapokat szükséges kitölteni, a ’PÁLYÁZÓ’ munkalap III. blokkjában a táblázat „Tennivaló” oszlopa jeleníti meg, hogy a táblázat melyik munkalapját szükséges tölteni. Egyes munkalapokon (’KAPCSOLÓDÓ PIAC’, ’KAPCSOLÓDÓ’, ’PARTNER’, ’KAPCSOLÓDÓ KÉK’, ’PARTNER KÉK’) az "F1" cellában található egy hivatkozás "VISSZA A PÁLYÁZÓ FÜLRE", melyre rákattintva a dokumentum legelejére navigál, a 'PÁLYÁZÓ' munkalapra. A 'PÁLYÁZÓ’ munkalap IV. blokkjában láthatóak az összesített adatok, mely alapján a KKV besorolást a táblázat automatikusan elvégzi a megadott üzleti évekre, ezeket az adatokat még tovább szükséges vizsgálni a kétéves szabály figyelembevételével. Amennyiben a pályázó vállalkozás olyan bonyolult kapcsolati hálóval rendelkezik, mely alapján a táblázat nem rendelkezik elegendő számú munkalapfüllel vagy egyéb észrevétele van, akkor azt a kozigprogramok@em.gov.hu e-mail címre jelezze.

Sheet PÁLYÁZÓ
A1: I. BLOKK: PÁLYÁZÓ VÁLLALKOZÁS SAJÁT ADATAI:
A2: I.1. ALBLOKK: PÁLYÁZÓ VÁLLALKOZÁS ALAPADATAI:
B3: Pályázó vállalkozás megnevezése: | D3: Amennyiben a vállalkozás érintett volt átalakulásban, akkor ennek típusát (pl.: beolvadás, kiválás, különválás, összeolvadás, formaváltás) szükséges rögzíteni az "Átalakulás típusa (ha releváns)" mezőben, valamint az "Utolsó átalakulás dátuma (ha releváns)" mezőben megadni annak időpontját. A cégközlönyben közzétett közlemény alapján szükséges az adatokat rögzíteni. Ha több alkalommal volt érintett a vállalkozás átalakulással, akkor a legutolsó átalakulásra vonatkozóan adja meg az adatot. Továbbá, ha jelenleg van folyamatban a vállalkozás átalakulása, akkor kérjük, hogy az erre vonatkozó körülményeket az "Egyéb információ az átalakulásról (ha releváns)" mezőben rögzítse.
B4: Pályázó vállalkozás adószáma:
B5: Vállalkozás alakulásának dátuma:
B6: Vállalkozás bejegyzésének dátuma:
B7: Utolsó átalakulás dátuma (ha releváns):
B8: Átalakulás típusa (ha releváns):
B9: Egyéb információ az átalakulásról (ha releváns):
A11: I.2. ALBLOKK: PÁLYÁZÓ VÁLLALKOZÁS GAZDÁLKODÁSI ADATAI:
B12: Kérjük adja meg az utolsó három lezárt üzleti évre vonatkozóan vállalkozása alábbi adatait. Természetesen, ha vállalkozása még csak egy vagy két lezárt üzleti évvel rendelkezik, csak azokra szolgáltasson adatot, a nem releváns sor üresen hagyandó. Amennyiben a vállalkozása esetén beszámoló közzétételi kötelezettsége áll fenn, az adatokat a https://e-beszamolo.im.gov.hu/oldal/kezdolap oldalról letölthető beszámolóival összhangban adja meg. Amennyiben beszámoló készítésére nem kötelezett a vállalkozás, akkor az adóbevallásban, illetve a nyilvántartásokban (pl. foglalkoztatottak száma) szerepelnek a releváns adatok, ebben az esetben a mérlegfőösszeg nem értelmezhető, ezért nem szükséges kitölteni. Kérjük, a kitöltésnél ügyeljen arra, hogy az e-beszámoló felületen az adatok ezer vagy millió forintban kerülnek feltüntetésre. Továbbá előfordulhat, hogy a beszámoló forinttól eltérő devizában készült. Kérjük, hogy a táblázatban a pontos összeget rögzítse, forintban megadva! Speciális esetek: Előfordulhat, hogy az alábbiak közül valamelyik üzleti év csak tört évként értelmezhető a pályázó vállalkozásnál. Ebben az esetben az árbevétel adatot évesíteni szükséges, a létszám adatot és a mérlegfőösszeget - ha az értelmezhető - azonban nem. Évesített árbevétel = (Tört év árbevétele / a beszámolóban szereplő működési napok száma) × adott év napjainak száma Amennyiben valamely üzleti évre adónem áttérés miatt két beszámoló készült, a következők szerint kell eljárni: az árbevétel adatokat össze kell adni, a két létszám adatból átlagot kell számolni, a mérlegfőösszeg adat esetén pedig az időben frissebb (második) adatot kell feltüntetni. Átlagos létszám = (Első beszámoló létszáma + Második beszámoló létszáma) / 2 N = utolsó lezárt üzleti év, N-1 = utolsó előtti lezárt év, N-2 = utolsó előtti lezárt évet megelőző év.
C13: Üzleti év kezdete | D13: Üzleti év vége | E13: Üzleti évben átlagosan foglalkoztatottak száma (fő) | F13: Éves nettó árbevétel (Ft) | G13: Mérlegfőösszeg (Ft) | N13: Alkalmazott devizaközépárfolyam | O13: Éves nettó árbevétel (euró) | P13: Mérlegfőösszeg (euró)
B14: N | N14: =IF(ISBLANK(D14),"",VLOOKUP(D14,'MNB árfolyam'!$A:$B,2,0)) | O14: =IFERROR(ROUND(F14/N14,0),0) -> 0 | P14: =IFERROR(ROUND(G14/N14,0),0) -> 0
B15: N-1 | N15: =IF(ISBLANK(D15),"",VLOOKUP(D15,'MNB árfolyam'!$A:$B,2,0)) | O15: =IFERROR(ROUND(F15/N15,0),0) -> 0 | P15: =IFERROR(ROUND(G15/N15,0),0) -> 0
B16: N-2 | N16: =IF(ISBLANK(D16),"",VLOOKUP(D16,'MNB árfolyam'!$A:$B,2,0)) | O16: =IFERROR(ROUND(F16/N16,0),0) -> 0 | P16: =IFERROR(ROUND(G16/N16,0),0) -> 0
B18: A KKV tv. szerint a KKV besoroláshoz meg kell állapítani, hogy a vállalkozás önálló, kapcsolódó vagy partner vállalkozásnak számít, melynek fogalmait a KKV tv. 4. §-a részletezi: "(3) Kapcsolódó vállalkozások azok, amelyek egymással az alábbiakban felsorolt valamely kapcsolatban állnak: a) egy vállalkozás egy másik vállalkozásban a szavazatok többségével rendelkezik, vagy b) egy vállalkozás egy másik vállalkozásban jogosult arra, hogy a vezető tisztségviselők vagy a felügyelő bizottság tagjai többségét megválassza vagy visszahívja, vagy c) egy vállalkozás egy másik vállalkozás felett a tulajdonosokkal (részvényesekkel) kötött szerződés vagy a létesítő okirat rendelkezése alapján – függetlenül a tulajdoni hányadtól, a szavazati aránytól, a megválasztási és visszahívási jogtól – döntő irányítást, ellenőrzést gyakorol, vagy d) egy vállalkozás egy másik vállalkozásban – más tulajdonosokkal (részvényesekkel) kötött megállapodás alapján – a szavazatok többségét egyedül birtokolja. (4) Kapcsolódó vállalkozásnak minősülnek azok a vállalkozások és a 19. § 1. pontjában meghatározott befektetők is, amelyek egy vagy több másik vállalkozáson keresztül állnak egymással a (3) bekezdésben meghatározott kapcsolatban. (5) Kapcsolódó vállalkozásnak minősülnek továbbá azok a vállalkozások, amelyek egy természetes személy vagy közösen fellépő természetes személyek egy csoportja révén a (3) és (4) bekezdésben meghatározott jellegű kapcsolatban állnak egymással, amennyiben tevékenységüket vagy tevékenységük egy részét az érintett piacon vagy egymással szomszédos piacokon folytatják." "(2) Partnervállalkozások azok a vállalkozások, a) amelyek nem minősülnek kapcsolódó vállalkozásoknak, és b) amelyek között olyan kapcsolat áll fenn, hogy egy vállalkozás kizárólagosan vagy egy vagy több kapcsolódó vállalkozással közösen valamely másik vállalkozás jegyzett tőkéjének vagy a szavazati jogának legalább 25%-ával rendelkezik." A KKV minősítés során meghatározott módszer szerint össze kell adni a kapcsolódó és/vagy partner vállalkozások adatait is. Látható, hogy a pályázó vállalkozás szempontjából kapcsolódó és/ vagy partner vállalkozási kapcsolat létrejöhet egyrészt a tulajdonosi körből kiindulva (ezt vesszük figyelembe a zöld hátterű blokkok és munkalapok segítségével). Másrészt fennállhat úgy is, hogy a pályázó vállalkozásnak van befolyása (részesedése, szavazati joga) más vállalkozásban (ezt a kék hátterű táblákkal, munkalapokkal vizsgáljuk).
A25: II. BLOKK: PÁLYÁZÓ VÁLLALKOZÁS TULAJDONOSAI, KAPCSOLÓDÓ ÉS PARTNER VÁLLALKOZÁSOK A TULAJDONOSI KÖR ALAPJÁN:
A26: II. 1. ALBLOKK: PÁLYÁZÓ VÁLLALKOZÁS TULAJDONOSAI:
B27: Kérjük, adja meg a pályázó vállalkozás tulajdonosait. A befolyás mértéke oszlopba, amennyiben a tulajdonos tulajdoni hányada és a szavazati joga eltérő mértékű, a magasabbat szükséges megadni. Mivel ezekkel az adatokkal még dolgozni fogunk, a harmadik oszlopban a legördülő listából válassza ki a tulajdonos releváns besorolását is. Besorolás meghatározása: 1. Természetes személy: Azon tulajdonosokat szükséges besorolni ebbe a kategóriába, akik természetes személyek és a KKV törvény alapján nem minősülnek vállalkozásnak. A KKV törvény 19. § 5. pontja határozza meg a vállalkozásokat, ha az adott természetes személy megfelel a fogalomnak, akkor a 2. Természetes személy, aki a KKV törvény szerint vállalkozásnak is minősül besorolást szükséges választani. Tehát például ha a tulajdonos egyben egyéni vállalkozó/mezőgazdasági őstermelő, akkor nem az 1. besorolási kategória választandó, hanem a 2. besorolás. 2. Természetes személy, aki a KKV törvény szerint vállalkozásnak is minősül: Azon tulajdonosokat szükséges ebbe a kategóriába besorolni, akik természetes személyek, azonban a KKV törvény 19. § 5. pontja alapján vállalkozásnak is minősül. Pl: egyéni vállalkozó, mezőgazdasági őstermelő. 3. Vállalkozás: Azon tulajdonosok sorolandóak 3. besorolási kategóriába, akik nem természetes személyek, hanem a támogatást igénylő vállalkozást egy másik vállalkozás tulajdonolja (részben vagy egészben). A vállalkozás fogalmát a KKV törvény 19. § 5. pontja határozza meg. Pl. Kft., Bt., Rt. 4. Befektető: Azon tulajdonosokat szükséges 4. befektető kategóriába rögzíteni, akik a KKV törvény 19. § 1. pontja alapján befektetőnek minősülnek. 5. Fentiekhez nem sorolható állami vagy önkormányzati tulajdonos: Az állami vagy önkormányzati tulajdonosokat szükséges rögzíteni ebbe a kategóriába. Fontos a befektetői besorolást megvizsgálni, mivel lehet, hogy önkormányzati vagy állami tulajdonú a támogatást igénylő, de a KKV törvény értelmében befektetőnek minősül, ebben az esetben a 4. kategóriát szükséges választani. Továbbá felhívjuk a figyelmet, hogy a KKV törvény 3.§ (4) bekezdése alapján nem minősül KKV-nak az a vállalkozás, amelyben az állam vagy az önkormányzat közvetlen vagy közvetett tulajdoni részesedése – tőke vagy szavazati joga alapján – külön-külön vagy együttesen eléri vagy meghaladja a 25%-ot. 6. Egyéb: A fentebbi kategóriák egyikébe sem sorolható egyéb tulajdonosokat szükséges jelölni ezzel a kategóriával. pl. civil szervezetek A Kapcsolat jellege oszlop automatikusan töltődik. Az Ellenőrzés oszlopban megjelenő figyelmeztetéseket kérjük vegye figyelembe. Speciális esetek: Ha a tulajdonosok között van olyan vállalkozás, amely jogosult arra, hogy a vezető tisztségviselők vagy a felügyelő bizottság tagjai többségét megválassza vagy visszahívja, illetve a tulajdonosokkal (részvényesekkel) kötött szerződés vagy a létesítő okirat rendelkezése alapján – függetlenül a tulajdoni hányadtól, a szavazati aránytól, a megválasztási és visszahívási jogtól – döntő irányítást, ellenőrzést gyakorol a KKV törvény alapján kapcsolódó vállalkozásnak minősül. Ezekben az esetekben a befolyás mértéke 50% felettiként szerepeljen a táblázatban.
B28: =IF(SUM(C30:C36)<100%,"A TULAJDONOSOK BEFOLYÁSA EGYÜTTESEN NEM ÉRI EL A MINIMUM 100%-OT. KÉRJÜK ELLENŐRIZZE AZ ADATOKAT!","A TULAJDONOSI BEFOLYÁS MÉRTÉKE MEGFELELŐEN RÖGZÍTETT.") -> A TULAJDONOSOK BEFOLYÁSA EGYÜTTESEN NEM ÉRI EL A MINIMUM 100%-OT. KÉRJÜK ELLENŐRIZZE AZ ADATOKAT!
B29: Tulajdonos | C29: Befolyás mértéke (százalék) | D29: Besorolás | E29: Kapcsolat jellege (automatikus) | F29: Ellenőrzés (automatikus)
E30: =IF(C30<25%,"",IF(AND(OR(D30="3. Vállalkozás",D30="2. Természetes személy, aki a KKV törvény szerint vállalkozásnak is minősül",D30="4. Befektető"),C30>50%),"KAPCSOLÓDÓ VÁLLALKOZÁS",IF(AND(OR(D30="3. Vállalkozás",D30="2. Természetes személy, aki a KKV törvény szerint vállalkozásnak is minősül"),AND(C30>=25%,C30<=50%)),"PARTNER VÁLLALKOZÁS",""))) | F30: =IF(B30="","",IF(AND(B30<>"",OR(C30="",D30="")),"Kérjük adja meg a befolyás mértékét és a besorolást is",IF(AND(D30="5. Fentiekhez nem sorolható állami vagy önkormányzati tulajdonos",C30>=25%)=TRUE,"Nem minősül KKV-nak az a vállalkozás, amelyben az állam vagy az önkormányzat közvetlen vagy közvetett tulajdoni részesedése – tőke vagy szavazati joga alapján – külön-külön vagy együttesen eléri, vagy meghaladja a 25%-ot.","OK"))) | N30: =IF(D30="1. Természetes személy",B30,"") | O30: =IF($E30="PARTNER VÁLLALKOZÁS",COUNTIF($E$30:$E30,"PARTNER VÁLLALKOZÁS"),"")
E31: =IF(C31<25%,"",IF(AND(OR(D31="3. Vállalkozás",D31="2. Természetes személy, aki a KKV törvény szerint vállalkozásnak is minősül",D31="4. Befektető"),C31>50%),"KAPCSOLÓDÓ VÁLLALKOZÁS",IF(AND(OR(D31="3. Vállalkozás",D31="2. Természetes személy, aki a KKV törvény szerint vállalkozásnak is minősül"),AND(C31>=25%,C31<=50%)),"PARTNER VÁLLALKOZÁS",""))) | F31: =IF(B31="","",IF(AND(B31<>"",OR(C31="",D31="")),"Kérjük adja meg a befolyás mértékét és a besorolást is",IF(AND(D31="5. Fentiekhez nem sorolható állami vagy önkormányzati tulajdonos",C31>=25%)=TRUE,"Nem minősül KKV-nak az a vállalkozás, amelyben az állam vagy az önkormányzat közvetlen vagy közvetett tulajdoni részesedése – tőke vagy szavazati joga alapján – külön-külön vagy együttesen eléri, vagy meghaladja a 25%-ot.","OK"))) | N31: =IF(D31="1. Természetes személy",B31,"") | O31: =IF($E31="PARTNER VÁLLALKOZÁS",COUNTIF($E$30:$E31,"PARTNER VÁLLALKOZÁS"),"")
E32: =IF(C32<25%,"",IF(AND(OR(D32="3. Vállalkozás",D32="2. Természetes személy, aki a KKV törvény szerint vállalkozásnak is minősül",D32="4. Befektető"),C32>50%),"KAPCSOLÓDÓ VÁLLALKOZÁS",IF(AND(OR(D32="3. Vállalkozás",D32="2. Természetes személy, aki a KKV törvény szerint vállalkozásnak is minősül"),AND(C32>=25%,C32<=50%)),"PARTNER VÁLLALKOZÁS",""))) | F32: =IF(B32="","",IF(AND(B32<>"",OR(C32="",D32="")),"Kérjük adja meg a befolyás mértékét és a besorolást is",IF(AND(D32="5. Fentiekhez nem sorolható állami vagy önkormányzati tulajdonos",C32>=25%)=TRUE,"Nem minősül KKV-nak az a vállalkozás, amelyben az állam vagy az önkormányzat közvetlen vagy közvetett tulajdoni részesedése – tőke vagy szavazati joga alapján – külön-külön vagy együttesen eléri, vagy meghaladja a 25%-ot.","OK"))) | N32: =IF(D32="1. Természetes személy",B32,"") | O32: =IF($E32="PARTNER VÁLLALKOZÁS",COUNTIF($E$30:$E32,"PARTNER VÁLLALKOZÁS"),"")
E33: =IF(C33<25%,"",IF(AND(OR(D33="3. Vállalkozás",D33="2. Természetes személy, aki a KKV törvény szerint vállalkozásnak is minősül",D33="4. Befektető"),C33>50%),"KAPCSOLÓDÓ VÁLLALKOZÁS",IF(AND(OR(D33="3. Vállalkozás",D33="2. Természetes személy, aki a KKV törvény szerint vállalkozásnak is minősül"),AND(C33>=25%,C33<=50%)),"PARTNER VÁLLALKOZÁS",""))) | F33: =IF(B33="","",IF(AND(B33<>"",OR(C33="",D33="")),"Kérjük adja meg a befolyás mértékét és a besorolást is",IF(AND(D33="5. Fentiekhez nem sorolható állami vagy önkormányzati tulajdonos",C33>=25%)=TRUE,"Nem minősül KKV-nak az a vállalkozás, amelyben az állam vagy az önkormányzat közvetlen vagy közvetett tulajdoni részesedése – tőke vagy szavazati joga alapján – külön-külön vagy együttesen eléri, vagy meghaladja a 25%-ot.","OK"))) | N33: =IF(D33="1. Természetes személy",B33,"") | O33: =IF($E33="PARTNER VÁLLALKOZÁS",COUNTIF($E$30:$E33,"PARTNER VÁLLALKOZÁS"),"")
E34: =IF(C34<25%,"",IF(AND(OR(D34="3. Vállalkozás",D34="2. Természetes személy, aki a KKV törvény szerint vállalkozásnak is minősül",D34="4. Befektető"),C34>50%),"KAPCSOLÓDÓ VÁLLALKOZÁS",IF(AND(OR(D34="3. Vállalkozás",D34="2. Természetes személy, aki a KKV törvény szerint vállalkozásnak is minősül"),AND(C34>=25%,C34<=50%)),"PARTNER VÁLLALKOZÁS",""))) | F34: =IF(B34="","",IF(AND(B34<>"",OR(C34="",D34="")),"Kérjük adja meg a befolyás mértékét és a besorolást is",IF(AND(D34="5. Fentiekhez nem sorolható állami vagy önkormányzati tulajdonos",C34>=25%)=TRUE,"Nem minősül KKV-nak az a vállalkozás, amelyben az állam vagy az önkormányzat közvetlen vagy közvetett tulajdoni részesedése – tőke vagy szavazati joga alapján – külön-külön vagy együttesen eléri, vagy meghaladja a 25%-ot.","OK"))) | N34: =IF(D34="1. Természetes személy",B34,"") | O34: =IF($E34="PARTNER VÁLLALKOZÁS",COUNTIF($E$30:$E34,"PARTNER VÁLLALKOZÁS"),"")
E35: =IF(C35<25%,"",IF(AND(OR(D35="3. Vállalkozás",D35="2. Természetes személy, aki a KKV törvény szerint vállalkozásnak is minősül",D35="4. Befektető"),C35>50%),"KAPCSOLÓDÓ VÁLLALKOZÁS",IF(AND(OR(D35="3. Vállalkozás",D35="2. Természetes személy, aki a KKV törvény szerint vállalkozásnak is minősül"),AND(C35>=25%,C35<=50%)),"PARTNER VÁLLALKOZÁS",""))) | F35: =IF(B35="","",IF(AND(B35<>"",OR(C35="",D35="")),"Kérjük adja meg a befolyás mértékét és a besorolást is",IF(AND(D35="5. Fentiekhez nem sorolható állami vagy önkormányzati tulajdonos",C35>=25%)=TRUE,"Nem minősül KKV-nak az a vállalkozás, amelyben az állam vagy az önkormányzat közvetlen vagy közvetett tulajdoni részesedése – tőke vagy szavazati joga alapján – külön-külön vagy együttesen eléri, vagy meghaladja a 25%-ot.","OK"))) | N35: =IF(D35="1. Természetes személy",B35,"") | O35: =IF($E35="PARTNER VÁLLALKOZÁS",COUNTIF($E$30:$E35,"PARTNER VÁLLALKOZÁS"),"")
E36: =IF(C36<25%,"",IF(AND(OR(D36="3. Vállalkozás",D36="2. Természetes személy, aki a KKV törvény szerint vállalkozásnak is minősül",D36="4. Befektető"),C36>50%),"KAPCSOLÓDÓ VÁLLALKOZÁS",IF(AND(OR(D36="3. Vállalkozás",D36="2. Természetes személy, aki a KKV törvény szerint vállalkozásnak is minősül"),AND(C36>=25%,C36<=50%)),"PARTNER VÁLLALKOZÁS",""))) | F36: =IF(B36="","",IF(AND(B36<>"",OR(C36="",D36="")),"Kérjük adja meg a befolyás mértékét és a besorolást is",IF(AND(D36="5. Fentiekhez nem sorolható állami vagy önkormányzati tulajdonos",C36>=25%)=TRUE,"Nem minősül KKV-nak az a vállalkozás, amelyben az állam vagy az önkormányzat közvetlen vagy közvetett tulajdoni részesedése – tőke vagy szavazati joga alapján – külön-külön vagy együttesen eléri, vagy meghaladja a 25%-ot.","OK"))) | N36: =IF(D36="1. Természetes személy",B36,"") | O36: =IF($E36="PARTNER VÁLLALKOZÁS",COUNTIF($E$30:$E36,"PARTNER VÁLLALKOZÁS"),"")
A38: II.2. ALBLOKK: NYILATKOZAT KÖZELI HOZZÁTARTOZÓKRÓL: | C38: =IF(COUNTIF($D30:$D36,"1. Természetes személy")>1,"KITÖLTENDŐ","NEM RELEVÁNS") -> NEM RELEVÁNS | D38: =IF(COUNTIF($D30:$D36,"1. Természetes személy")>1,"",K38) -> A II. 1. ALBLOKKBAN NEM KERÜLT RÖGZÍTÉSRE TERMÉSZETES SZEMÉLY, VAGY KEVESEBB, MINT KÉT TERMÉSZETES SZEMÉLY KERÜLT RÖGZÍTÉSRE, MINT TULAJDONOS, EZÉRT NEM ÉRTELMEZHETŐ A KÖZELI HOZZÁTARTOZÓI VISZONYRÓL TETT NYILATKOZAT, ÍGY EZ AZ ALBLOKK NEM KITÖLTENDŐ! FOLYTASSA A KITÖLTÉST A II.3. ALBLOKKNÁL! | K38: A II. 1. ALBLOKKBAN NEM KERÜLT RÖGZÍTÉSRE TERMÉSZETES SZEMÉLY, VAGY KEVESEBB, MINT KÉT TERMÉSZETES SZEMÉLY KERÜLT RÖGZÍTÉSRE, MINT TULAJDONOS, EZÉRT NEM ÉRTELMEZHETŐ A KÖZELI HOZZÁTARTOZÓI VISZONYRÓL TETT NYILATKOZAT, ÍGY EZ AZ ALBLOKK NEM KITÖLTENDŐ! FOLYTASSA A KITÖLTÉST A II.3. ALBLOKKNÁL!
B39: A KKV besorolás megállapításakor törvényi előírás szerint természetes személy tulajdonosok esetén figyelembe kell venni, hogy a természetes személyek közeli hozzátartozók-e, mivel a közeli hozzátartozók közvetlen és közvetett tulajdoni részesedését vagy szavazati jogát egybe kell számítani. Közeli hozzátartozó a Ptk. 8:1 § (1) bekezdés 1. pontja alapján a házastárs, az egyeneságbeli rokon (gyermek, unoka, szülő, nagyszülő), az örökbefogadott, a mostoha- és a nevelt gyermek, az örökbefogadó-, a mostoha- és a nevelőszülő és a testvér. Kérjük nyilatkozzon az alábbi legördülő menü segítségével, hogy a fent bemutatott természetes személy tulajdonosok között van-e közeli hozzátartozói kapcsolat, és amennyiben igen, a táblázatban nevesítse ezeket. Csak azokról a természetes személy tulajdonosokról kell nyilatkozni, akik a fenti táblában az 1-es besorolást kaptak, nem kell tehát figyelembe venni a 2-es besorolási kategóriát.
B45: Közeli hozzátartozók 1-es csoport
C46: Befolyás mértéke | D46: Indoklás
C47: =IF(B47="","",VLOOKUP(B47,$B$30:$C$36,2,0))
C48: =IF(B48="","",VLOOKUP(B48,$B$30:$C$36,2,0))
C49: =IF(B49="","",VLOOKUP(B49,$B$30:$C$36,2,0))
C50: =IF(B50="","",VLOOKUP(B50,$B$30:$C$36,2,0))
C51: =IF(B51="","",VLOOKUP(B51,$B$30:$C$36,2,0))
C52: =IF(B52="","",VLOOKUP(B52,$B$30:$C$36,2,0))
C53: =IF(B53="","",VLOOKUP(B53,$B$30:$C$36,2,0))
B54: Befolyás mértéke összesen | C54: =SUM(C47:C53) -> 0
...

Sheet Segédtábla
C1: =SUM(C3:C22) -> 0 | D1: =SUM(D3:D22) -> 0 | E1: =SUM(E3:E22) -> 0 | F1: =SUM(F3:F22) -> 0 | G1: =SUM(G3:G22) -> 0 | H1: =SUM(H3:H22) -> 0 | I1: =SUM(I3:I22) -> 0 | J1: =SUM(J3:J22) -> 0 | K1: =SUM(K3:K22) -> 0
A2: KÉK tábla | B2: Vállalkozás neve | C2: N foglalkoztatottak száma (fő) | D2: N Éves nettó árbevétel (euró) | E2: N Mérlegfőösszeg (euró) | F2: N-1 foglalkoztatottak száma (fő) | G2: N-1 Éves nettó árbevétel (euró) | H2: N-1 Mérlegfőösszeg (euró) | I2: N-2 foglalkoztatottak száma (fő) | J2: N-2 Éves nettó árbevétel (euró) | K2: N-2 Mérlegfőösszeg (euró)
A3: Kapcsolódó KÉK 1 | B3: ='KAPCSOLÓDÓ KÉK1'!B8 -> 0 | C3: ='KAPCSOLÓDÓ KÉK1'!B3 -> 0 | D3: ='KAPCSOLÓDÓ KÉK1'!C3 -> 0 | E3: ='KAPCSOLÓDÓ KÉK1'!D3 -> 0 | F3: ='KAPCSOLÓDÓ KÉK1'!B4 -> 0 | G3: ='KAPCSOLÓDÓ KÉK1'!C4 -> 0 | H3: ='KAPCSOLÓDÓ KÉK1'!D4 -> 0 | I3: ='KAPCSOLÓDÓ KÉK1'!B5 -> 0 | J3: ='KAPCSOLÓDÓ KÉK1'!C5 -> 0 | K3: ='KAPCSOLÓDÓ KÉK1'!D5 -> 0
A4: Kapcsolódó KÉK 2 | B4: ='KAPCSOLÓDÓ KÉK2'!B8 -> 0 | C4: ='KAPCSOLÓDÓ KÉK2'!B3 -> 0 | D4: ='KAPCSOLÓDÓ KÉK2'!C3 -> 0 | E4: ='KAPCSOLÓDÓ KÉK2'!D3 -> 0 | F4: ='KAPCSOLÓDÓ KÉK2'!B4 -> 0 | G4: ='KAPCSOLÓDÓ KÉK2'!C4 -> 0 | H4: ='KAPCSOLÓDÓ KÉK2'!D4 -> 0 | I4: ='KAPCSOLÓDÓ KÉK2'!B5 -> 0 | J4: ='KAPCSOLÓDÓ KÉK2'!C5 -> 0 | K4: ='KAPCSOLÓDÓ KÉK2'!D5 -> 0
A5: Kapcsolódó KÉK 3 | B5: ='KAPCSOLÓDÓ KÉK3'!B8 -> 0 | C5: ='KAPCSOLÓDÓ KÉK3'!B3 -> 0 | D5: ='KAPCSOLÓDÓ KÉK3'!C3 -> 0 | E5: ='KAPCSOLÓDÓ KÉK3'!D3 -> 0 | F5: ='KAPCSOLÓDÓ KÉK3'!B4 -> 0 | G5: ='KAPCSOLÓDÓ KÉK3'!C4 -> 0 | H5: ='KAPCSOLÓDÓ KÉK3'!D4 -> 0 | I5: ='KAPCSOLÓDÓ KÉK3'!B5 -> 0 | J5: ='KAPCSOLÓDÓ KÉK3'!C5 -> 0 | K5: ='KAPCSOLÓDÓ KÉK3'!D5 -> 0
A6: Kapcsolódó KÉK 4 | B6: ='KAPCSOLÓDÓ KÉK4'!B8 -> 0 | C6: ='KAPCSOLÓDÓ KÉK4'!B3 -> 0 | D6: ='KAPCSOLÓDÓ KÉK4'!C3 -> 0 | E6: ='KAPCSOLÓDÓ KÉK4'!D3 -> 0 | F6: ='KAPCSOLÓDÓ KÉK4'!B4 -> 0 | G6: ='KAPCSOLÓDÓ KÉK4'!C4 -> 0 | H6: ='KAPCSOLÓDÓ KÉK4'!D4 -> 0 | I6: ='KAPCSOLÓDÓ KÉK4'!B5 -> 0 | J6: ='KAPCSOLÓDÓ KÉK4'!C5 -> 0 | K6: ='KAPCSOLÓDÓ KÉK4'!D5 -> 0
A7: Kapcsolódó KÉK 5 | B7: ='KAPCSOLÓDÓ KÉK5'!B8 -> 0 | C7: ='KAPCSOLÓDÓ KÉK5'!B3 -> 0 | D7: ='KAPCSOLÓDÓ KÉK5'!C3 -> 0 | E7: ='KAPCSOLÓDÓ KÉK5'!D3 -> 0 | F7: ='KAPCSOLÓDÓ KÉK5'!B4 -> 0 | G7: ='KAPCSOLÓDÓ KÉK5'!C4 -> 0 | H7: ='KAPCSOLÓDÓ KÉK5'!D4 -> 0 | I7: ='KAPCSOLÓDÓ KÉK5'!B5 -> 0 | J7: ='KAPCSOLÓDÓ KÉK5'!C5 -> 0 | K7: ='KAPCSOLÓDÓ KÉK5'!D5 -> 0
A8: Kapcsolódó KÉK 6 | B8: ='KAPCSOLÓDÓ KÉK6'!B8 -> 0 | C8: ='KAPCSOLÓDÓ KÉK6'!B3 -> 0 | D8: ='KAPCSOLÓDÓ KÉK6'!C3 -> 0 | E8: ='KAPCSOLÓDÓ KÉK6'!D3 -> 0 | F8: ='KAPCSOLÓDÓ KÉK6'!B4 -> 0 | G8: ='KAPCSOLÓDÓ KÉK6'!C4 -> 0 | H8: ='KAPCSOLÓDÓ KÉK6'!D4 -> 0 | I8: ='KAPCSOLÓDÓ KÉK6'!B5 -> 0 | J8: ='KAPCSOLÓDÓ KÉK6'!C5 -> 0 | K8: ='KAPCSOLÓDÓ KÉK6'!D5 -> 0
A9: Kapcsolódó KÉK 7 | B9: ='KAPCSOLÓDÓ KÉK7'!B8 -> 0 | C9: ='KAPCSOLÓDÓ KÉK7'!B3 -> 0 | D9: ='KAPCSOLÓDÓ KÉK7'!C3 -> 0 | E9: ='KAPCSOLÓDÓ KÉK7'!D3 -> 0 | F9: ='KAPCSOLÓDÓ KÉK7'!B4 -> 0 | G9: ='KAPCSOLÓDÓ KÉK7'!C4 -> 0 | H9: ='KAPCSOLÓDÓ KÉK7'!D4 -> 0 | I9: ='KAPCSOLÓDÓ KÉK7'!B5 -> 0 | J9: ='KAPCSOLÓDÓ KÉK7'!C5 -> 0 | K9: ='KAPCSOLÓDÓ KÉK7'!D5 -> 0
A10: Kapcsolódó KÉK 8 | B10: ='KAPCSOLÓDÓ KÉK8'!B8 -> 0 | C10: ='KAPCSOLÓDÓ KÉK8'!B3 -> 0 | D10: ='KAPCSOLÓDÓ KÉK8'!C3 -> 0 | E10: ='KAPCSOLÓDÓ KÉK8'!D3 -> 0 | F10: ='KAPCSOLÓDÓ KÉK8'!B4 -> 0 | G10: ='KAPCSOLÓDÓ KÉK8'!C4 -> 0 | H10: ='KAPCSOLÓDÓ KÉK8'!D4 -> 0 | I10: ='KAPCSOLÓDÓ KÉK8'!B5 -> 0 | J10: ='KAPCSOLÓDÓ KÉK8'!C5 -> 0 | K10: ='KAPCSOLÓDÓ KÉK8'!D5 -> 0
A11: Kapcsolódó KÉK 9 | B11: ='KAPCSOLÓDÓ KÉK9'!B8 -> 0 | C11: ='KAPCSOLÓDÓ KÉK9'!B3 -> 0 | D11: ='KAPCSOLÓDÓ KÉK9'!C3 -> 0 | E11: ='KAPCSOLÓDÓ KÉK9'!D3 -> 0 | F11: ='KAPCSOLÓDÓ KÉK9'!B4 -> 0 | G11: ='KAPCSOLÓDÓ KÉK9'!C4 -> 0 | H11: ='KAPCSOLÓDÓ KÉK9'!D4 -> 0 | I11: ='KAPCSOLÓDÓ KÉK9'!B5 -> 0 | J11: ='KAPCSOLÓDÓ KÉK9'!C5 -> 0 | K11: ='KAPCSOLÓDÓ KÉK9'!D5 -> 0
A12: Kapcsolódó KÉK 10 | B12: ='KAPCSOLÓDÓ KÉK10'!B8 -> 0 | C12: ='KAPCSOLÓDÓ KÉK10'!B3 -> 0 | D12: ='KAPCSOLÓDÓ KÉK10'!C3 -> 0 | E12: ='KAPCSOLÓDÓ KÉK10'!D3 -> 0 | F12: ='KAPCSOLÓDÓ KÉK10'!B4 -> 0 | G12: ='KAPCSOLÓDÓ KÉK10'!C4 -> 0 | H12: ='KAPCSOLÓDÓ KÉK10'!D4 -> 0 | I12: ='KAPCSOLÓDÓ KÉK10'!B5 -> 0 | J12: ='KAPCSOLÓDÓ KÉK10'!C5 -> 0 | K12: ='KAPCSOLÓDÓ KÉK10'!D5 -> 0
A13: Partner KÉK 1 | B13: ='PARTNER KÉK1'!B8 -> 0 | C13: ='PARTNER KÉK1'!B3 | D13: ='PARTNER KÉK1'!C3 | E13: ='PARTNER KÉK1'!D3 | F13: ='PARTNER KÉK1'!B4 | G13: ='PARTNER KÉK1'!C4 | H13: ='PARTNER KÉK1'!D4 | I13: ='PARTNER KÉK1'!B5 | J13: ='PARTNER KÉK1'!C5 | K13: ='PARTNER KÉK1'!D5
A14: Partner KÉK 2 | B14: ='PARTNER KÉK2'!B8 -> 0 | C14: ='PARTNER KÉK2'!B3 | D14: ='PARTNER KÉK2'!C3 | E14: ='PARTNER KÉK2'!D3 | F14: ='PARTNER KÉK2'!B4 | G14: ='PARTNER KÉK2'!C4 | H14: ='PARTNER KÉK2'!D4 | I14: ='PARTNER KÉK2'!B5 | J14: ='PARTNER KÉK2'!C5 | K14: ='PARTNER KÉK2'!D5
A15: Partner KÉK 3 | B15: ='PARTNER KÉK3'!B8 -> 0 | C15: ='PARTNER KÉK3'!B3 | D15: ='PARTNER KÉK3'!C3 | E15: ='PARTNER KÉK3'!D3 | F15: ='PARTNER KÉK3'!B4 | G15: ='PARTNER KÉK3'!C4 | H15: ='PARTNER KÉK3'!D4 | I15: ='PARTNER KÉK3'!B5 | J15: ='PARTNER KÉK3'!C5 | K15: ='PARTNER KÉK3'!D5
A16: Partner KÉK 4 | B16: ='PARTNER KÉK4'!B8 -> 0 | C16: ='PARTNER KÉK4'!B3 | D16: ='PARTNER KÉK4'!C3 | E16: ='PARTNER KÉK4'!D3 | F16: ='PARTNER KÉK4'!B4 | G16: ='PARTNER KÉK4'!C4 | H16: ='PARTNER KÉK4'!D4 | I16: ='PARTNER KÉK4'!B5 | J16: ='PARTNER KÉK4'!C5 | K16: ='PARTNER KÉK4'!D5
A17: Partner KÉK 5 | B17: ='PARTNER KÉK5'!B8 -> 0 | C17: ='PARTNER KÉK5'!B3 | D17: ='PARTNER KÉK5'!C3 | E17: ='PARTNER KÉK5'!D3 | F17: ='PARTNER KÉK5'!B4 | G17: ='PARTNER KÉK5'!C4 | H17: ='PARTNER KÉK5'!D4 | I17: ='PARTNER KÉK5'!B5 | J17: ='PARTNER KÉK5'!C5 | K17: ='PARTNER KÉK5'!D5
A18: Partner KÉK 6 | B18: ='PARTNER KÉK6'!B8 -> 0 | C18: ='PARTNER KÉK6'!B3 | D18: ='PARTNER KÉK6'!C3 | E18: ='PARTNER KÉK6'!D3 | F18: ='PARTNER KÉK6'!B4 | G18: ='PARTNER KÉK6'!C4 | H18: ='PARTNER KÉK6'!D4 | I18: ='PARTNER KÉK6'!B5 | J18: ='PARTNER KÉK6'!C5 | K18: ='PARTNER KÉK6'!D5
A19: Partner KÉK 7 | B19: ='PARTNER KÉK7'!B8 -> 0 | C19: ='PARTNER KÉK7'!B3 | D19: ='PARTNER KÉK7'!C3 | E19: ='PARTNER KÉK7'!D3 | F19: ='PARTNER KÉK7'!B4 | G19: ='PARTNER KÉK7'!C4 | H19: ='PARTNER KÉK7'!D4 | I19: ='PARTNER KÉK7'!B5 | J19: ='PARTNER KÉK7'!C5 | K19: ='PARTNER KÉK7'!D5
A20: Partner KÉK 8 | B20: ='PARTNER KÉK8'!B8 -> 0 | C20: ='PARTNER KÉK8'!B3 | D20: ='PARTNER KÉK8'!C3 | E20: ='PARTNER KÉK8'!D3 | F20: ='PARTNER KÉK8'!B4 | G20: ='PARTNER KÉK8'!C4 | H20: ='PARTNER KÉK8'!D4 | I20: ='PARTNER KÉK8'!B5 | J20: ='PARTNER KÉK8'!C5 | K20: ='PARTNER KÉK8'!D5
A21: Partner KÉK 9 | B21: ='PARTNER KÉK9'!B8 -> 0 | C21: ='PARTNER KÉK9'!B3 | D21: ='PARTNER KÉK9'!C3 | E21: ='PARTNER KÉK9'!D3 | F21: ='PARTNER KÉK9'!B4 | G21: ='PARTNER KÉK9'!C4 | H21: ='PARTNER KÉK9'!D4 | I21: ='PARTNER KÉK9'!B5 | J21: ='PARTNER KÉK9'!C5 | K21: ='PARTNER KÉK9'!D5
A22: Partner KÉK 10 | B22: ='PARTNER KÉK10'!B8 -> 0 | C22: ='PARTNER KÉK10'!B3 | D22: ='PARTNER KÉK10'!C3 | E22: ='PARTNER KÉK10'!D3 | F22: ='PARTNER KÉK10'!B4 | G22: ='PARTNER KÉK10'!C4 | H22: ='PARTNER KÉK10'!D4 | I22: ='PARTNER KÉK10'!B5 | J22: ='PARTNER KÉK10'!C5 | K22: ='PARTNER KÉK10'!D5
C24: =SUM(C26:C36) -> 0 | D24: =SUM(D26:D36) -> 0 | E24: =SUM(E26:E36) -> 0 | F24: =SUM(F26:F36) -> 0 | G24: =SUM(G26:G36) -> 0 | H24: =SUM(H26:H36) -> 0 | I24: =SUM(I26:I36) -> 0 | J24: =SUM(J26:J36) -> 0 | K24: =SUM(K26:K36) -> 0
A25: ZÖLD tábla | B25: Vállalkozás neve | C25: N foglalkoztatottak száma (fő) | D25: N Éves nettó árbevétel (euró) | E25: N Mérlegfőösszeg (euró) | F25: N-1 foglalkoztatottak száma (fő) | G25: N-1 Éves nettó árbevétel (euró) | H25: N-1 Mérlegfőösszeg (euró) | I25: N-2 foglalkoztatottak száma (fő) | J25: N-2 Éves nettó árbevétel (euró) | K25: N-2 Mérlegfőösszeg (euró)
A26: Kapcsolódó | B26: =KAPCSOLÓDÓ!B8 | C26: =KAPCSOLÓDÓ!B3 -> 0 | D26: =KAPCSOLÓDÓ!C3 -> 0 | E26: =KAPCSOLÓDÓ!D3 -> 0 | F26: =KAPCSOLÓDÓ!B4 -> 0 | G26: =KAPCSOLÓDÓ!C4 -> 0 | H26: =KAPCSOLÓDÓ!D4 -> 0 | I26: =KAPCSOLÓDÓ!B5 -> 0 | J26: =KAPCSOLÓDÓ!C5 -> 0 | K26: =KAPCSOLÓDÓ!D5 -> 0
A27: Kapcsolódó Piac 1 | B27: ='KAPCSOLÓDÓ PIAC1'!B8 -> 0 | C27: ='KAPCSOLÓDÓ PIAC1'!B3 -> 0 | D27: ='KAPCSOLÓDÓ PIAC1'!C3 -> 0 | E27: ='KAPCSOLÓDÓ PIAC1'!D3 -> 0 | F27: ='KAPCSOLÓDÓ PIAC1'!B4 -> 0 | G27: ='KAPCSOLÓDÓ PIAC1'!C4 -> 0 | H27: ='KAPCSOLÓDÓ PIAC1'!D4 -> 0 | I27: ='KAPCSOLÓDÓ PIAC1'!B5 -> 0 | J27: ='KAPCSOLÓDÓ PIAC1'!C5 -> 0 | K27: ='KAPCSOLÓDÓ PIAC1'!D5 -> 0
A28: Kapcsolódó Piac 2 | B28: ='KAPCSOLÓDÓ PIAC2'!B8 -> 0 | C28: ='KAPCSOLÓDÓ PIAC2'!B3 -> 0 | D28: ='KAPCSOLÓDÓ PIAC2'!C3 -> 0 | E28: ='KAPCSOLÓDÓ PIAC2'!D3 -> 0 | F28: ='KAPCSOLÓDÓ PIAC2'!B4 -> 0 | G28: ='KAPCSOLÓDÓ PIAC2'!C4 -> 0 | H28: ='KAPCSOLÓDÓ PIAC2'!D4 -> 0 | I28: ='KAPCSOLÓDÓ PIAC2'!B5 -> 0 | J28: ='KAPCSOLÓDÓ PIAC2'!C5 -> 0 | K28: ='KAPCSOLÓDÓ PIAC2'!D5 -> 0
A29: Kapcsolódó Piac 3 | B29: ='KAPCSOLÓDÓ PIAC3'!B8 -> 0 | C29: ='KAPCSOLÓDÓ PIAC3'!B3 -> 0 | D29: ='KAPCSOLÓDÓ PIAC3'!C3 -> 0 | E29: ='KAPCSOLÓDÓ PIAC3'!D3 -> 0 | F29: ='KAPCSOLÓDÓ PIAC3'!B4 -> 0 | G29: ='KAPCSOLÓDÓ PIAC3'!C4 -> 0 | H29: ='KAPCSOLÓDÓ PIAC3'!D4 -> 0 | I29: ='KAPCSOLÓDÓ PIAC3'!B5 -> 0 | J29: ='KAPCSOLÓDÓ PIAC3'!C5 -> 0 | K29: ='KAPCSOLÓDÓ PIAC3'!D5 -> 0
A30: Kapcsolódó Piac 4 | B30: ='KAPCSOLÓDÓ PIAC4'!B8 -> 0 | C30: ='KAPCSOLÓDÓ PIAC4'!B3 -> 0 | D30: ='KAPCSOLÓDÓ PIAC4'!C3 -> 0 | E30: ='KAPCSOLÓDÓ PIAC4'!D3 -> 0 | F30: ='KAPCSOLÓDÓ PIAC4'!B4 -> 0 | G30: ='KAPCSOLÓDÓ PIAC4'!C4 -> 0 | H30: ='KAPCSOLÓDÓ PIAC4'!D4 -> 0 | I30: ='KAPCSOLÓDÓ PIAC4'!B5 -> 0 | J30: ='KAPCSOLÓDÓ PIAC4'!C5 -> 0 | K30: ='KAPCSOLÓDÓ PIAC4'!D5 -> 0
A31: Kapcsolódó Piac 5 | B31: ='KAPCSOLÓDÓ PIAC5'!B8 -> 0 | C31: ='KAPCSOLÓDÓ PIAC5'!B3 -> 0 | D31: ='KAPCSOLÓDÓ PIAC5'!C3 -> 0 | E31: ='KAPCSOLÓDÓ PIAC5'!D3 -> 0 | F31: ='KAPCSOLÓDÓ PIAC5'!B4 -> 0 | G31: ='KAPCSOLÓDÓ PIAC5'!C4 -> 0 | H31: ='KAPCSOLÓDÓ PIAC5'!D4 -> 0 | I31: ='KAPCSOLÓDÓ PIAC5'!B5 -> 0 | J31: ='KAPCSOLÓDÓ PIAC5'!C5 -> 0 | K31: ='KAPCSOLÓDÓ PIAC5'!D5 -> 0
A32: Kapcsolódó Piac 6 | B32: ='KAPCSOLÓDÓ PIAC6'!B8 -> 0 | C32: ='KAPCSOLÓDÓ PIAC6'!B3 -> 0 | D32: ='KAPCSOLÓDÓ PIAC6'!C3 -> 0 | E32: ='KAPCSOLÓDÓ PIAC6'!D3 -> 0 | F32: ='KAPCSOLÓDÓ PIAC6'!B4 -> 0 | G32: ='KAPCSOLÓDÓ PIAC6'!C4 -> 0 | H32: ='KAPCSOLÓDÓ PIAC6'!D4 -> 0 | I32: ='KAPCSOLÓDÓ PIAC6'!B5 -> 0 | J32: ='KAPCSOLÓDÓ PIAC6'!C5 -> 0 | K32: ='KAPCSOLÓDÓ PIAC6'!D5 -> 0
A33: Partner 1 | B33: =PARTNER1!B8 | C33: =PARTNER1!B3 | D33: =PARTNER1!C3 | E33: =PARTNER1!D3 | F33: =PARTNER1!B4 | G33: =PARTNER1!C4 | H33: =PARTNER1!D4 | I33: =PARTNER1!B5 | J33: =PARTNER1!C5 | K33: =PARTNER1!D5
A34: Partner 2 | B34: =PARTNER2!B8 | C34: =PARTNER2!B3 | D34: =PARTNER2!C3 | E34: =PARTNER2!D3 | F34: =PARTNER2!B4 | G34: =PARTNER2!C4 | H34: =PARTNER2!D4 | I34: =PARTNER2!B5 | J34: =PARTNER2!C5 | K34: =PARTNER2!D5
A35: Partner 3 | B35: =PARTNER3!B8 | C35: =PARTNER3!B3 | D35: =PARTNER3!C3 | E35: =PARTNER3!D3 | F35: =PARTNER3!B4 | G35: =PARTNER3!C4 | H35: =PARTNER3!D4 | I35: =PARTNER3!B5 | J35: =PARTNER3!C5 | K35: =PARTNER3!D5
A36: Partner 4 | B36: =PARTNER4!B8 | C36: =PARTNER4!B3 | D36: =PARTNER4!C3 | E36: =PARTNER4!D3 | F36: =PARTNER4!B4 | G36: =PARTNER4!C4 | H36: =PARTNER4!D4 | I36: =PARTNER4!B5 | J36: =PARTNER4!C5 | K36: =PARTNER4!D5

Sheet MNB árfolyam
A1: Dátum | B1: 1 Euro/Ft | C1: hét napja képlet | D1: hét napja
A2: 43466 | B2: 321.51 | C2: 2 | D2: kedd
A3: 43467 | B3: 322.16 | C3: 3 | D3: szerda | J3: Összes foglalkoztatotti létszám | K3: Éves nettó árbevétel | L3: Mérlegfőösszeg
A4: 43468 | B4: 322.55 | C4: 4 | D4: csütörtök | I4: Középvállalkozás | J4: < 250 fő | K4: ≤ 50 millió euró | L4: ≤ 43 millió euró
A5: 43469 | B5: 321.25 | C5: 5 | D5: péntek | I5: Kisvállalkozás | J5: < 50 fő | K5: ≤ 10 millió euró | L5: ≤ 10 millió euró
A6: 43470 | B6: 321.25 | C6: 6 | D6: szombat | I6: Mikrovállalkozás | J6: <10 fő | K6: ≤ 2 millió euró | L6: ≤ 2 millió euró
A7: 43471 | B7: 321.25 | C7: 7 | D7: vasárnap
A8: 43472 | B8: 321.18 | C8: 1 | D8: hétfő | I8: N | J8: N-1 | K8: N-2 | L8: KKV státusza
A9: 43473 | B9: 321.4 | C9: 2 | D9: kedd | I9: KÖZÉP | J9: KIS | K9: - | L9: KIS (bázis év)
A10: 43474 | B10: 321.78 | C10: 3 | D10: szerda | I10: KÖZÉP | J10: KIS | K10: MIKRO | L10: KÖZÉP (kétszer felfelé)
A11: 43475 | B11: 321.75 | C11: 4 | D11: csütörtök | I11: MIKRO | J11: KIS | K11: KÖZÉP | L11: MIKRO (kétszer lefelé)
A12: 43476 | B12: 321.4 | C12: 5 | D12: péntek | I12: MIKRO | J12: KIS | K12: MIKRO | L12: ?
A13: 43477 | B13: 321.4 | C13: 6 | D13: szombat
A14: 43478 | B14: 321.4 | C14: 7 | D14: vasárnap
A15: 43479 | B15: 321.17 | C15: 1 | D15: hétfő
A16: 43480 | B16: 321.8 | C16: 2 | D16: kedd
A17: 43481 | B17: 323.52 | C17: 3 | D17: szerda
A18: 43482 | B18: 321.44 | C18: 4 | D18: csütörtök
A19: 43483 | B19: 318.92 | C19: 5 | D19: péntek
A20: 43484 | B20: 318.92 | C20: 6 | D20: szombat
A21: 43485 | B21: 318.92 | C21: 7 | D21: vasárnap
A22: 43486 | B22: 318.2 | C22: 1 | D22: hétfő
A23: 43487 | B23: 318 | C23: 2 | D23: kedd
A24: 43488 | B24: 318.11 | C24: 3 | D24: szerda
... A2612: 46076 | B2612: 379.9 | C2612: 1 | D2612: hétfő
A2613: 46077
A2614: 46078
A2615: 46079
A2616: 46080
A2617: 46081
A2618: 46082
A2619: 46083
A2620: 46084
A2621: 46085
A2622: 46086
A2623: 46087
A2624: 46088
... A2683: 46147

Sheet Tulajdonos besorolás opciók
A1: A | B1: Természetes személy, aki nem folytat vállalkozói tevékenységet | D1: NEM, a fentiekben felsorolt természetes személy tulajdonosok között NINCS a Ptk. 8:1 § (1) bekezdés szerinti közeli hozzátartozói kapcsolat.
A2: B | B2: Természetes személy, aki egyben egyéni vállalkozó, vagy önálló vállalkozó is (pl. egyéni ügyvéd, közjegyző, bírósági végrehajtó) | D2: IGEN, a fentiekben felsorolt természetes személy tulajdonosok között vannak olyanok, akik közeli hozzátartozók, a következők szerint Az alábbi táblába a legördülő listából válassza ki azokat a természetes személy tulajdonosokat, akik egymásnak közeli hozzátartozói és az indoklás oszlopba röviden mutassa be a kapcsolat jellegét pl. XY és AB férj és feleség. Ha a közeli hozzátartozók több egymástól független csoportba sorolhatók - pl. XY és AB férj és feleség valamint GK és VB is férj és feleség, de a két házaspár között nincs közeli hozzátartozói kapcsolat, akkor két csoportot rögzítsen. Ha a két házaspár között is van közeli hozzátartozó, pl. szülő, gyermek kapcsolat, akkor mindenki egy csoportban szerepeljen.
A3: C | B3: Vállalkozás (pl. gazdasági társaság, szövetkezet)
A4: D | B4: Befektető, amely lehet:
B5: • állami befektetési társaság • finanszírozáshoz való hozzáférés elősegítése céljából rendszeresen kockázatitőke-befektetést folytató egyén vagy csoport, aki vagy amely a tőzsdén nem jegyzett vállalkozások alaptőkéjébe fektet be, azzal a feltétellel, hogy az ugyanazon vállalkozásban eszközölt összes befektetése legfeljebb 1 250 000 eurónak megfelelő forintösszeg • felsőoktatási intézmény, nem felsőoktatási intézmény szervezetében működő oktatási és szaktanácsadási intézmény, felső- vagy középfokú oktatás gyakorlati háttereként termelőtevékenységet folytató tangazdaság és tanüzem, nonprofit kutatási központ, valamint nem felsőoktatási intézmény szervezeteként – költségvetési szervként működő – egyéb kutatóhely • intézményi befektető, beleértve a regionális fejlesztési alapokat; • önálló helyi önkormányzat, amely költségvetése 10 millió eurónál kisebb, és a lakosok száma 5000 főnél kevesebb | D5: NEM, a pályázó vállalkozásnak NINCS legalább 25%-ot elérő befolyása más vállalkozás(ok)ban.
D6: IGEN, a pályázó vállalkozásnak VAN legalább 25%-ot elérő befolyása más vállalkozás(ok)ban. Ezúton nyilatkozom, hogy minden érintett vállalkozás adatát feltöltöttem az alábbi táblázatba.
A10: E | B10: fentiekhez nem sorolható állami vagy önkormányzati tulajdonos
A11: F | B11: Jogi személyiségű vagy jogi személyiség nélküli nonprofit szervezet
B16: 1. Természetes személy
B17: 2. Természetes személy, aki a KKV törvény szerint vállalkozásnak is minősül
B18: 3. Vállalkozás
B19: 4. Befektető
B20: 5. Fentiekhez nem sorolható állami vagy önkormányzati tulajdonos
B21: 6. Egyéb
B31: 2. Természetes személy, aki egyben egyéni vállalkozó, vagy önálló vállalkozó is (pl. egyéni ügyvéd, közjegyző, bírósági végrehajtó)
B32: 3. Vállalkozás (pl. gazdasági társaság, vagy szövetkezet)
B33: 4. Befektető (pontos definícióját a xxx tartalmazza)
B34: 5. Fentiekhez nem sorolható állami vagy önkormányzati tulajdonos
B35: 6. Egyéb (pl. nonprofit szervezet)

Sheet KAPCSOLÓDÓ PIAC1
A1: Kapcsolódó vállalkozás összesítő (automatikusan töltődik, ezt a blokkot Önnek nem kell töltenie): | F1: VISSZA A PÁLYÁZÓ FÜLRE
B2: Üzleti évben átlagosan foglalkoztatottak száma (fő) | C2: Éves nettó árbevétel (euró) | D2: Mérlegfőösszeg (euró)
A3: N | B3: =D14+E24+BI54 -> 0 | C3: =AX14+AX24+BJ54 -> 0 | D3: =AY14+AY24+BK54 -> 0
A4: N-1 | B4: =D15+J24+BL54 -> 0 | C4: =AX15+BA24+BM54 -> 0 | D4: =AY15+BB24+BN54 -> 0
A5: N-2 | B5: =D16+O24+BO54 -> 0 | C5: =AX16+BD24+BP54 -> 0 | D5: =AY16+BE24+BQ54 -> 0
A7: I. BLOKK: KAPCSOLÓDÓ VÁLLALKOZÁS SAJÁT ADATAI:
A8: Kapcsolódó vállalkozás megnevezése (automatikusan töltődik a PÁLYÁZÓ munkalapról): | B8: =PÁLYÁZÓ!B86 -> 0
A9: Kapcsolódó vállalkozás adószáma (automatikusan töltődik a PÁLYÁZÓ munkalapról): | B9: =PÁLYÁZÓ!C86 -> 0
A11: Kérjük, adja meg ennek a vállalkozásnak a gazdálkodási adatait főszabály szerint az utolsó három lezárt üzleti évre vonatkozóan. FONTOS: Ha a pályázó vállalkozásnak csak egy vagy két lezárt üzleti éve van, ennek a vállalkozásnak is csak azokra az évekre szükséges feltüntetni az adatait. Amennyiben a pályázó vállalkozás rendelkezik 2025. évre szóló beszámolóval (N év adata), ugyanakkor a kapcsolódó vállalkozásnak még nem készült el a beszámolója, kérjük az üzleti év kezdete és vége adatokat töltse fel, de más adatokat az N évre vonatkozóan nem szükséges feltüntetni. Ha a kapcsolódó vállalkozás rendelkezik 2025 évi beszámolóval, de a pályázó vállalkozás még nem, akkor a 2025 évi beszámolót nem kell feltüntetni. Amennyiben a vállalkozás esetén beszámoló közzétételi kötelezettség áll fenn, az adatokat a https://e-beszamolo.im.gov.hu/oldal/kezdolap oldalról letölthető beszámolóival összhangban adja meg. Amennyiben beszámoló készítésére nem kötelezett a vállalkozás, akkor az adóbevallásban, illetve a nyilvántartásokban (pl. foglalkoztatottak száma) szerepelnek a releváns adatok, ebben az esetben a mérlegfőösszeg nem értelmezhető, ezért nem szükséges kitölteni. Kérjük, a kitöltésnél ügyeljen arra, hogy az e-beszámoló felületen az adatok ezer vagy millió forintban kerülnek feltüntetésre. Továbbá előfordulhat, hogy a beszámoló forinttól eltérő devizában készült. Kérjük, hogy a táblázatban a pontos összeget rögzítse, forintban megadva! Speciális esetek: Előfordulhat, hogy az alábbiak közül valamelyik üzleti év csak tört évként értelmezhető a kapcsolódó vállalkozásnál. Ebben az esetben az árbevétel adatot évesíteni szükséges, a létszám adatot és a mérlegfőösszeget - ha az értelmezhető - azonban nem. Évesített árbevétel = (Tört év árbevétele / a beszámolóban szereplő működési napok száma) × az adott év napjainak száma Amennyiben valamely üzleti évre adónem áttérés miatt két beszámoló készült, a következők szerint kell eljárni: az árbevétel adatokat össze kell adni, a két létszám adatból átlagot kell számolni, a mérlegfőösszeg adat esetén pedig az időben frissebb (második) adatot kell feltüntetni. Átlagos létszám = (Első beszámoló létszáma + Második beszámoló létszáma) / 2 N = utolsó lezárt üzleti év, N-1 = utolsó előtti lezárt év, N-2 = utolsó előtti lezárt évet megelőző év.
A12: =IF(PÁLYÁZÓ!D16<>"","A pályázó vállalkozás három üzleti évre adta meg az adatokat, ezért a kapcsolódó vállalkozás esetén is három évre kérünk adatot, ha a vállalkozás működött ebben az időtartamban.",IF(PÁLYÁZÓ!D15<>"","A pályázó vállalkozás két üzleti évre adta meg az adatokat, ezért a kapcsolódó vállalkozás esetén is két évre kérünk adatot, ha a vállalkozás működött ebben az időtartamban.",IF(PÁLYÁZÓ!D14<>"","A pályázó vállalkozás egy üzleti évre adta meg az adatokat, ezért a kapcsolódó vállalkozás esetén is egy évre kérünk adatot, ha a vállalkozás működött ebben az időtartamban.","")))
B13: Üzleti év kezdete | C13: Üzleti év vége | D13: Üzleti évben átlagosan foglalkoztatottak száma (fő) | E13: Éves nettó árbevétel (forint) | F13: Mérlegfőösszeg (Ft) | AW13: Alkalmazott devizaközépárfolyam | AX13: Éves nettó árbevétel (euró) | AY13: Mérlegfőösszeg (euró)
A14: N | AW14: =IF(C14="","",VLOOKUP(C14,'MNB árfolyam'!A:B,2,0)) | AX14: =IFERROR(ROUND(E14/AW15,0),0) -> 0 | AY14: =IFERROR(ROUND(F14/AW14,0),0) -> 0
A15: N-1 | AW15: =IF(C15="","",VLOOKUP(C15,'MNB árfolyam'!A:B,2,0)) | AX15: =IFERROR(ROUND(E15/AW15,0),0) -> 0 | AY15: =IFERROR(ROUND(F15/AW15,0),0) -> 0
A16: N-2 | AW16: =IF(C16="","",VLOOKUP(C16,'MNB árfolyam'!A:B,2,0)) | AX16: =IFERROR(ROUND(E16/AW16,0),0) -> 0 | AY16: =IFERROR(ROUND(F16/AW16,0),0) -> 0
A18: A KKV besorolás megállapításához a törvény alapján figyelembe kell venni a pályázó vállalkozás kapcsolódó vállalkozásának a kapcsolódó és partner vállalkozásait is.Figyelembe vesszük azokat a vállalkozásokat is, akik a pályázó kapcsolódó vállalkozását tulajdonolják, és azokat is, akikre a kapcsolódó vállalkozásnak van befolyása, ezért szerepelnek a nyilak két irányba a 3. ábrán. Az alábbi két külön táblázatba szükséges az adatokat feltüntetni.
A21: =CONCATENATE("II. BLOKK: ",B8," ","KAPCSOLÓDÓ VÁLLALKOZÁSAI:") -> II. BLOKK: 0 KAPCSOLÓDÓ VÁLLALKOZÁSAI:
A22: Az alábbiakban fel kell tüntetni a pályázó vállalkozás természetes személyen keresztüli kapcsolódó vállakozásának (amelyről ez a munkalap szól) a KAPCSOLÓDÓ VÁLLALKOZÁSAIT. Jelen esetben tehát azokat a vállalkozásokat, amelyekben a pályázó vállalkozás kapcsolódó vállalkozása 50%-nál nagyobb befolyással bír. Annyi évre vonatkozóan kell adatot szolgáltatni, amennyi lezárt üzleti évvel a pályázó vállalkozás rendelkezik. FONTOS TUDNIVALÓK: Ha a pályázó vállalkozásnak csak egy vagy két lezárt üzleti éve van, az itt feltüntetett vállalkozásoknak is csak azokra az évekre szükséges feltüntetni az adatait. Amennyiben a pályázó vállalkozás rendelkezik 2025. évre szóló beszámolóval (N év adata), ugyanakkor a kapcsolódó vállalkozásoknak még nem készült el a beszámolója, kérjük az üzleti év kezdete és vége adatokat töltse fel, de más adatokat az N évre vonatkozóan nem szükséges feltüntetni. Ha a kapcsolódó vállalkozás rendelkezik 2025. évi beszámolóval, de a pályázó vállalkozás még nem, a 2025. évi adatokat nem kell feltüntetni. Amennyiben a vállalkozás esetén beszámoló közzétételi kötelezettség áll fenn, az adatokat a https://e-beszamolo.im.gov.hu/oldal/kezdolap oldalról letölthető beszámolóival összhangban adja meg. Amennyiben beszámoló készítésére nem kötelezett a vállalkozás, akkor az adóbevallásban, illetve a nyilvántartásokban (pl. foglalkoztatottak száma) szerepelnek a releváns adatok, ebben az esetben a mérlegfőösszeg nem értelmezhető, ezért nem szükséges kitölteni. Kérjük, a kitöltésnél ügyeljen arra, hogy az e-beszámoló felületen az adatok ezer vagy millió forintban kerülnek feltüntetésre. Továbbá előfordulhat, hogy a beszámoló forinttól eltérő devizában készült. Kérjük, hogy a táblázatban a pontos összeget rögzítse, forintban megadva! Speciális esetek: Előfordulhat, hogy az alábbiak közül valamelyik üzleti év csak tört évként értelmezhető a kapcsolódó vállalkozásnál. Ebben az esetben az árbevétel adatot évesíteni szükséges, a létszám adatot és a mérlegfőösszeget - ha az értelmezhető - azonban nem. Évesített árbevétel = (Tört év árbevétele / a beszámolóban szereplő működési napok száma) × az adott év napjainak száma Amennyiben valamely üzleti évre adónem áttérés miatt két beszámoló készült, a következők szerint kell eljárni: az árbevétel adatokat össze kell adni, a két létszám adatból átlagot kell számolni, a mérlegfőösszeg adat esetén pedig az időben frissebb (második) adatot kell feltüntetni. Átlagos létszám = (Első beszámoló létszáma + Második beszámoló létszáma) / 2 N = utolsó lezárt üzleti év, N-1 = utolsó előtti lezárt év, N-2 = utolsó előtti lezárt évet megelőző év.
A23: =A12
E24: =SUM(E26:E50) -> 0 | J24: =SUM(J26:J50) -> 0 | O24: =SUM(O26:O50) -> 0 | AX24: =SUM(AX26:AX50) -> 0 | AY24: =SUM(AY26:AY50) -> 0 | BA24: =SUM(BA26:BA50) -> 0 | BB24: =SUM(BB26:BB50) -> 0 | BD24: =SUM(BD26:BD50) -> 0 | BE24: =SUM(BE26:BE50) -> 0
A25: =CONCATENATE(B8," ","Kapcsolódó vállalkozásának neve") -> 0 Kapcsolódó vállalkozásának neve | B25: Kapcsolódó vállalkozás adószáma | C25: N üzleti év kezdete | D25: N üzleti év vége | E25: N üzleti évben átlagosan foglalkoztatottak száma (fő) | F25: N üzleti év éves nettó árbevétele (Ft) | G25: N üzleti év mérlegfőösszege (Ft) | H25: N-1 üzleti év kezdete | I25: N-1 üzleti év vége | J25: N-1 üzleti évben átlagosan foglalkoztatottak száma (fő) | K25: N-1 üzleti év éves nettó árbevétele (Ft) | L25: N-1 üzleti év mérlegfőösszege (Ft) | M25: N-2 üzleti év kezdete | N25: N-2 üzleti év vége | O25: N-2 üzleti évben átlagosan foglalkoztatottak száma (fő) | P25: N-2 üzleti év éves nettó árbevétele (Ft) | Q25: N-2 üzleti év mérlegfőösszege (Ft) | AW25: N év Alkalmazott devizaközépárfolyam | AX25: N üzleti év Éves nettó árbevétel (euró) | AY25: N üzleti év Mérlegfőösszeg (euró) | AZ25: N-1 év Alkalmazott devizaközépárfolyam | BA25: N-1év Éves nettó árbevétel (euró) | BB25: N-1 év Mérlegfőösszeg (euró) | BC25: N-2 év Alkalmazott devizaközépárfolyam | BD25: N-2 év Éves nettó árbevétel (euró) | BE25: N-2 év Mérlegfőösszeg (euró)
AW26: =IF(D26="","",VLOOKUP(D26,'MNB árfolyam'!A:B,2,0)) | AX26: =IF(ISBLANK(F26),"",ROUND(F26/AW26,0)) | AY26: =IF(ISBLANK(G26),"",ROUND(G26/AW26,0)) | AZ26: =IF(I26="","",VLOOKUP(I26,'MNB árfolyam'!A:B,2,0)) | BA26: =IF(ISBLANK(K26),"",ROUND(K26/AZ26,0)) | BB26: =IF(ISBLANK(L26),"",ROUND(L26/AZ26,0)) | BC26: =IF(N26="","",VLOOKUP(N26,'MNB árfolyam'!A:B,2,0)) | BD26: =IF(ISBLANK(P26),"",ROUND(P26/BC26,0)) | BE26: =IF(ISBLANK(Q26),"",ROUND(Q26/BC26,0))
AW27: =IF(D27="","",VLOOKUP(D27,'MNB árfolyam'!A:B,2,0)) | AX27: =IF(ISBLANK(F27),"",ROUND(F27/AW27,0)) | AY27: =IF(ISBLANK(G27),"",ROUND(G27/AW27,0)) | AZ27: =IF(I27="","",VLOOKUP(I27,'MNB árfolyam'!A:B,2,0)) | BA27: =IF(ISBLANK(K27),"",ROUND(K27/AZ27,0)) | BB27: =IF(ISBLANK(L27),"",ROUND(L27/AZ27,0)) | BC27: =IF(N27="","",VLOOKUP(N27,'MNB árfolyam'!A:B,2,0)) | BD27: =IF(ISBLANK(P27),"",ROUND(P27/BC27,0)) | BE27: =IF(ISBLANK(Q27),"",ROUND(Q27/BC27,0))
AW28: =IF(D28="","",VLOOKUP(D28,'MNB árfolyam'!A:B,2,0)) | AX28: =IF(ISBLANK(F28),"",ROUND(F28/AW28,0)) | AY28: =IF(ISBLANK(G28),"",ROUND(G28/AW28,0)) | AZ28: =IF(I28="","",VLOOKUP(I28,'MNB árfolyam'!A:B,2,0)) | BA28: =IF(ISBLANK(K28),"",ROUND(K28/AZ28,0)) | BB28: =IF(ISBLANK(L28),"",ROUND(L28/AZ28,0)) | BC28: =IF(N28="","",VLOOKUP(N28,'MNB árfolyam'!A:B,2,0)) | BD28: =IF(ISBLANK(P28),"",ROUND(P28/BC28,0)) | BE28: =IF(ISBLANK(Q28),"",ROUND(Q28/BC28,0))
AW29: =IF(D29="","",VLOOKUP(D29,'MNB árfolyam'!A:B,2,0)) | AX29: =IF(ISBLANK(F29),"",ROUND(F29/AW29,0)) | AY29: =IF(ISBLANK(G29),"",ROUND(G29/AW29,0)) | AZ29: =IF(I29="","",VLOOKUP(I29,'MNB árfolyam'!A:B,2,0)) | BA29: =IF(ISBLANK(K29),"",ROUND(K29/AZ29,0)) | BB29: =IF(ISBLANK(L29),"",ROUND(L29/AZ29,0)) | BC29: =IF(N29="","",VLOOKUP(N29,'MNB árfolyam'!A:B,2,0)) | BD29: =IF(ISBLANK(P29),"",ROUND(P29/BC29,0)) | BE29: =IF(ISBLANK(Q29),"",ROUND(Q29/BC29,0))
AW30: =IF(D30="","",VLOOKUP(D30,'MNB árfolyam'!A:B,2,0)) | AX30: =IF(ISBLANK(F30),"",ROUND(F30/AW30,0)) | AY30: =IF(ISBLANK(G30),"",ROUND(G30/AW30,0)) | AZ30: =IF(I30="","",VLOOKUP(I30,'MNB árfolyam'!A:B,2,0)) | BA30: =IF(ISBLANK(K30),"",ROUND(K30/AZ30,0)) | BB30: =IF(ISBLANK(L30),"",ROUND(L30/AZ30,0)) | BC30: =IF(N30="","",VLOOKUP(N30,'MNB árfolyam'!A:B,2,0)) | BD30: =IF(ISBLANK(P30),"",ROUND(P30/BC30,0)) | BE30: =IF(ISBLANK(Q30),"",ROUND(Q30/BC30,0))
AW31: =IF(D31="","",VLOOKUP(D31,'MNB árfolyam'!A:B,2,0)) | AX31: =IF(ISBLANK(F31),"",ROUND(F31/AW31,0)) | AY31: =IF(ISBLANK(G31),"",ROUND(G31/AW31,0)) | AZ31: =IF(I31="","",VLOOKUP(I31,'MNB árfolyam'!A:B,2,0)) | BA31: =IF(ISBLANK(K31),"",ROUND(K31/AZ31,0)) | BB31: =IF(ISBLANK(L31),"",ROUND(L31/AZ31,0)) | BC31: =IF(N31="","",VLOOKUP(N31,'MNB árfolyam'!A:B,2,0)) | BD31: =IF(ISBLANK(P31),"",ROUND(P31/BC31,0)) | BE31: =IF(ISBLANK(Q31),"",ROUND(Q31/BC31,0))
AW32: =IF(D32="","",VLOOKUP(D32,'MNB árfolyam'!A:B,2,0)) | AX32: =IF(ISBLANK(F32),"",ROUND(F32/AW32,0)) | AY32: =IF(ISBLANK(G32),"",ROUND(G32/AW32,0)) | AZ32: =IF(I32="","",VLOOKUP(I32,'MNB árfolyam'!A:B,2,0)) | BA32: =IF(ISBLANK(K32),"",ROUND(K32/AZ32,0)) | BB32: =IF(ISBLANK(L32),"",ROUND(L32/AZ32,0)) | BC32: =IF(N32="","",VLOOKUP(N32,'MNB árfolyam'!A:B,2,0)) | BD32: =IF(ISBLANK(P32),"",ROUND(P32/BC32,0)) | BE32: =IF(ISBLANK(Q32),"",ROUND(Q32/BC32,0))
AW33: =IF(D33="","",VLOOKUP(D33,'MNB árfolyam'!A:B,2,0)) | AX33: =IF(ISBLANK(F33),"",ROUND(F33/AW33,0)) | AY33: =IF(ISBLANK(G33),"",ROUND(G33/AW33,0)) | AZ33: =IF(I33="","",VLOOKUP(I33,'MNB árfolyam'!A:B,2,0)) | BA33: =IF(ISBLANK(K33),"",ROUND(K33/AZ33,0)) | BB33: =IF(ISBLANK(L33),"",ROUND(L33/AZ33,0)) | BC33: =IF(N33="","",VLOOKUP(N33,'MNB árfolyam'!A:B,2,0)) | BD33: =IF(ISBLANK(P33),"",ROUND(P33/BC33,0)) | BE33: =IF(ISBLANK(Q33),"",ROUND(Q33/BC33,0))
